Workbook
Name MY_FUNCTION1: LAMBDA(COVARIANCE.P(Reliance!$K$3:$K$496,Reliance!$L$3:$L$496)/VARP(Reliance!$L$3:$L$496))

Sheet Reliance
A1: DATE | B1: OPEN | C1: HIGH | D1: LOW | E1: PREV. CLOSE | F1: CLOSE | G1: VWAP | H1: VOLUME | I1: VALUE | J1: NO. OF TRADES | K1: Daily Return | L1: NIFTY RETURN
A2: 45509 | B2: 2960 | C2: 2967.8 | D2: 2866.5 | E2: 2998.65 | F2: 2894.65 | G2: 2901.81 | H2: 85,23,352 | I2: 24,73,31,28,212.00 | J2: 4,48,630 | M2: =VALUE(SUBSTITUTE(H2,",","")) -> 8523352
A3: 45510 | B3: 2910.3 | C3: 2955 | D3: 2902.65 | E3: 2894.65 | F3: 2912.1 | G3: 2929.53 | H3: 51,18,093 | I3: 14,99,35,89,440.05 | J3: 1,97,549 | K3: 0.0060283627 | L3: -0.0026210113 | M3: =VALUE(SUBSTITUTE(H3,",","")) -> 5118093
A4: 45511 | B4: 2938 | C4: 2945 | D4: 2923 | E4: 2912.1 | F4: 2929.65 | G4: 2930.89 | H4: 40,87,284 | I4: 11,97,93,63,870.55 | J4: 2,76,362 | K4: 0.0060265788 | L4: 0.012710195 | M4: =VALUE(SUBSTITUTE(H4,",","")) -> 4087284
A5: 45512 | B5: 2915.05 | C5: 2930 | D5: 2891.85 | E5: 2929.65 | F5: 2898.25 | G5: 2905.69 | H5: 61,93,596 | I5: 17,99,66,62,105.65 | J5: 2,55,138 | K5: -0.010718004 | L5: -0.0074287478 | M5: =VALUE(SUBSTITUTE(H5,",","")) -> 6193596
A6: 45513 | B6: 2920 | C6: 2953 | D6: 2912 | E6: 2898.25 | F6: 2948.6 | G6: 2939.2 | H6: 31,24,888 | I6: 9,18,46,80,574.05 | J6: 1,50,169 | K6: 0.017372552 | L6: 0.010386864 | M6: =VALUE(SUBSTITUTE(H6,",","")) -> 3124888
A7: 45516 | B7: 2940 | C7: 2946 | D7: 2915.5 | E7: 2948.6 | F7: 2921.25 | G7: 2929.82 | H7: 40,92,292 | I7: 11,98,96,80,025.65 | J7: 1,88,301 | K7: -0.0092755884 | L7: -0.0008412845 | M7: =VALUE(SUBSTITUTE(H7,",","")) -> 4092292
A8: 45517 | B8: 2921.5 | C8: 2940.15 | D8: 2916 | E8: 2921.25 | F8: 2927.25 | G8: 2928.29 | H8: 31,32,532 | I8: 9,17,29,71,802.70 | J8: 1,34,517 | K8: 0.0020539153 | L8: -0.008543147 | M8: =VALUE(SUBSTITUTE(H8,",","")) -> 3132532
A9: 45518 | B9: 2927.1 | C9: 2944 | D9: 2907.4 | E9: 2927.25 | F9: 2923.7 | G9: 2925.78 | H9: 31,33,733 | I9: 9,16,86,16,380.80 | J9: 1,85,733 | K9: -0.0012127423 | L9: 0.000196777 | M9: =VALUE(SUBSTITUTE(H9,",","")) -> 3133733
A10: 45520 | B10: 2937.3 | C10: 2960.8 | D10: 2916.1 | E10: 2923.7 | F10: 2956.4 | G10: 2944.77 | H10: 47,08,451 | I10: 13,86,53,25,209.75 | J10: 1,87,365 | K10: 0.011184458 | L10: 0.016459746 | M10: =VALUE(SUBSTITUTE(H10,",","")) -> 4708451
A11: 45523 | B11: 2965 | C11: 2996.6 | D11: 2961 | E11: 2956.4 | F11: 2976.8 | G11: 2980.25 | H11: 68,98,871 | I11: 20,56,03,27,724.60 | J11: 2,00,328 | K11: 0.0069002841 | L11: 0.0012835584 | M11: =VALUE(SUBSTITUTE(H11,",","")) -> 6898871
A12: 45524 | B12: 2994.45 | C12: 3007.85 | D12: 2980.05 | E12: 2976.8 | F12: 2991.9 | G12: 2996.98 | H12: 42,05,904 | I12: 12,60,50,24,714.40 | J12: 1,75,516 | K12: 0.0050725611 | L12: 0.0051357912 | M12: =VALUE(SUBSTITUTE(H12,",","")) -> 4205904
A13: 45525 | B13: 2986.5 | C13: 3015.75 | D13: 2980 | E13: 2991.9 | F13: 2997.35 | G13: 3001.42 | H13: 38,84,998 | I13: 11,66,05,26,038.60 | J13: 1,41,353 | K13: 0.0018215849 | L13: 0.0028887985 | M13: =VALUE(SUBSTITUTE(H13,",","")) -> 3884998
A14: 45526 | B14: 3006 | C14: 3013 | D14: 2981.3 | E14: 2997.35 | F14: 2996.25 | G14: 2994.88 | H14: 52,22,891 | I14: 15,64,19,35,953.20 | J14: 2,33,216 | K14: -0.00036699084 | L14: 0.0016673261 | M14: =VALUE(SUBSTITUTE(H14,",","")) -> 5222891
... A59: 45590 | B59: 2687 | C59: 2688.7 | D59: 2644 | E59: 2679.6 | F59: 2655.7 | G59: 2659.8 | H59: 92,98,748 | I59: 24,73,28,26,126.10 | J59: 3,88,238 | K59: -0.0089192417 | L59: -0.0089592367 | M59: =VALUE(SUBSTITUTE(H59,",","")) -> 9298748
A60: 45593 | B60: 1337 | C60: 1353 | D60: 1322.1 | E60: 2655.7 | F60: 1334.35 | G60: 1337.7 | H60: 1,08,24,350 | I60: 14,47,97,33,719.25 | J60: 3,68,817 | L60: 0.006548584 | M60: =VALUE(SUBSTITUTE(H60,",","")) -> 10824350
A61: 45594 | B61: 1328.1 | C61: 1343.2 | D61: 1320.3 | E61: 1334.35 | F61: 1340 | G61: 1331.46 | H61: 1,20,08,361 | I61: 15,98,86,83,034.00 | J61: 4,36,915 | K61: 0.0042342714 | L61: 0.005246691 | M61: =VALUE(SUBSTITUTE(H61,",","")) -> 12008361
A62: 45595 | B62: 1335 | C62: 1350 | D62: 1325.35 | E62: 1340 | F62: 1343.9 | G62: 1341.16 | H62: 1,19,84,423 | I62: 16,07,30,73,274.15 | J62: 2,95,954 | K62: 0.0029104478 | L62: -0.0051498252 | M62: =VALUE(SUBSTITUTE(H62,",","")) -> 11984423
A63: 45596 | B63: 1340 | C63: 1343 | D63: 1326.15 | E63: 1343.9 | F63: 1332.05 | G63: 1334.14 | H63: 93,31,650 | I63: 12,44,97,44,606.90 | J63: 4,14,741 | K63: -0.0088176204 | L63: -0.0055667736 | M63: =VALUE(SUBSTITUTE(H63,",","")) -> 9331650
A64: 45597 | B64: 1333.05 | C64: 1341.95 | D64: 1333 | E64: 1332.05 | F64: 1338.65 | G64: 1338.89 | H64: 21,27,335 | I64: 2,84,82,64,119.80 | J64: 1,27,374 | K64: 0.004954769 | L64: 0.0040900049 | M64: =VALUE(SUBSTITUTE(H64,",","")) -> 2127335
A65: 45600 | B65: 1337.85 | C65: 1340 | D65: 1285.1 | E65: 1338.65 | F65: 1302.15 | G65: 1301.44 | H65: 1,97,96,890 | I65: 25,76,44,50,096.55 | J65: 5,54,958 | K65: -0.027266276 | L65: -0.012713773 | M65: =VALUE(SUBSTITUTE(H65,",","")) -> 19796890
A66: 45601 | B66: 1293 | C66: 1309.55 | D66: 1286.15 | E66: 1302.15 | F66: 1305.3 | G66: 1297.87 | H66: 1,62,67,479 | I66: 21,11,31,19,455.50 | J66: 3,71,758 | K66: 0.0024190761 | L66: 0.0090830098 | M66: =VALUE(SUBSTITUTE(H66,",","")) -> 16267479
A67: 45602 | B67: 1310 | C67: 1328.3 | D67: 1300.2 | E67: 1305.3 | F67: 1325.35 | G67: 1315.57 | H67: 2,16,25,209 | I67: 28,44,95,04,045.35 | J67: 3,49,627 | K67: 0.015360454 | L67: 0.011181871 | M67: =VALUE(SUBSTITUTE(H67,",","")) -> 21625209
A68: 45603 | B68: 1324 | C68: 1324 | D68: 1302.6 | E68: 1325.35 | F68: 1305.65 | G68: 1308.97 | H68: 96,11,974 | I68: 12,58,18,00,339.00 | J68: 2,61,277 | K68: -0.014863998 | L68: -0.011627978 | M68: =VALUE(SUBSTITUTE(H68,",","")) -> 9611974
A69: 45604 | B69: 1297.65 | C69: 1301.65 | D69: 1275 | E69: 1305.65 | F69: 1283.75 | G69: 1284.01 | H69: 1,98,14,406 | I69: 25,44,19,00,935.60 | J69: 4,77,001 | K69: -0.016773255 | L69: -0.0021136931 | M69: =VALUE(SUBSTITUTE(H69,",","")) -> 19814406
A70: 45607 | B70: 1278.95 | C70: 1286 | D70: 1267 | E70: 1283.75 | F70: 1272.7 | G70: 1275.44 | H70: 90,56,552 | I70: 11,55,10,68,872.50 | J70: 2,86,019 | K70: -0.0086075949 | L70: -0.00028573558 | M70: =VALUE(SUBSTITUTE(H70,",","")) -> 9056552
A71: 45608 | B71: 1275.55 | C71: 1289.3 | D71: 1267.5 | E71: 1272.7 | F71: 1274.25 | G71: 1277.82 | H71: 1,06,71,091 | I71: 13,63,56,94,812.30 | J71: 2,99,780 | K71: 0.0012178832 | L71: -0.010680866 | M71: =VALUE(SUBSTITUTE(H71,",","")) -> 10671091
A72: 45609 | B72: 1270.25 | C72: 1275.45 | D72: 1249.5 | E72: 1274.25 | F72: 1252.05 | G72: 1258.62 | H72: 1,46,33,633 | I72: 18,41,82,08,535.90 | J72: 4,69,215 | K72: -0.017422013 | L72: -0.013582627 | M72: =VALUE(SUBSTITUTE(H72,",","")) -> 14633633
... A303: 45950 | B303: 1440 | C303: 1473.8 | D303: 1433.3 | E303: 1416.8 | F303: 1466.8 | G303: 1461.76 | H303: 2,47,21,978 | I303: 36,13,76,73,257.50 | J303: 5,12,798 | K303: 0.035290796 | L303: 0.0051847833 | M303: =VALUE(SUBSTITUTE(H303,",","")) -> 24721978
A304: 45951 | B304: 1468 | C304: 1474 | D304: 1460 | E304: 1466.8 | F304: 1465.2 | G304: 1467.87 | H304: 20,66,169 | I304: 3,03,28,61,642.80 | J304: 86819 | K304: -0.0010908099 | L304: 0.00098478707 | M304: =VALUE(SUBSTITUTE(H304,",","")) -> 2066169
A305: 45953 | B305: 1475 | C305: 1482.9 | D305: 1444.6 | E305: 1465.2 | F305: 1448.4 | G305: 1464.71 | H305: 1,87,07,090 | I305: 27,40,03,74,842.50 | J305: 3,76,220 | K305: -0.011466011 | L305: 0.00088137742 | M305: =VALUE(SUBSTITUTE(H305,",","")) -> 18707090
A306: 45954 | B306: 1450 | C306: 1459.8 | D306: 1441 | E306: 1448.4 | F306: 1451.6 | G306: 1450.25 | H306: 97,00,837 | I306: 14,06,86,22,023.20 | J306: 2,21,258 | K306: 0.0022093344 | L306: -0.0037174506 | M306: =VALUE(SUBSTITUTE(H306,",","")) -> 9700837
A307: 45957 | B307: 1463 | C307: 1485 | D307: 1458 | E307: 1451.6 | F307: 1484.1 | G307: 1480.24 | H307: 1,41,13,867 | I307: 20,89,18,82,342.50 | J307: 2,74,839 | K307: 0.022389088 | L307: 0.0066252765 | M307: =VALUE(SUBSTITUTE(H307,",","")) -> 14113867
A308: 45958 | B308: 1484.1 | C308: 1492 | D308: 1477.6 | E308: 1484.1 | F308: 1486.9 | G308: 1484.96 | H308: 1,76,31,577 | I308: 26,18,22,48,923.90 | J308: 3,14,894 | K308: 0.0018866653 | L308: -0.001149578 | M308: =VALUE(SUBSTITUTE(H308,",","")) -> 17631577
A309: 45959 | B309: 1490 | C309: 1508.3 | D309: 1488.1 | E309: 1486.9 | F309: 1504.2 | G309: 1502.67 | H309: 1,18,84,745 | I309: 17,85,88,00,582.60 | J309: 2,19,504 | K309: 0.011634945 | L309: 0.0045380588 | M309: =VALUE(SUBSTITUTE(H309,",","")) -> 11884745
A310: 45960 | B310: 1500 | C310: 1503.1 | D310: 1484 | E310: 1504.2 | F310: 1488.5 | G310: 1492.27 | H310: 93,18,663 | I310: 13,90,59,20,959.90 | J310: 2,76,397 | K310: -0.010437442 | L310: -0.0067571458 | M310: =VALUE(SUBSTITUTE(H310,",","")) -> 9318663
A311: 45961 | B311: 1490.4 | C311: 1497.5 | D311: 1482.3 | E311: 1488.5 | F311: 1486.4 | G311: 1487.8 | H311: 87,58,053 | I311: 13,03,02,57,785.30 | J311: 2,06,898 | K311: -0.0014108163 | L311: -0.0060186607 | M311: =VALUE(SUBSTITUTE(H311,",","")) -> 8758053
A312: 45964 | B312: 1486 | C312: 1495 | D312: 1479.3 | E312: 1486.4 | F312: 1484.7 | G312: 1488.29 | H312: 84,52,085 | I312: 12,57,91,61,982.90 | J312: 2,45,664 | K312: -0.0011437029 | L312: 0.0016036793 | M312: =VALUE(SUBSTITUTE(H312,",","")) -> 8452085
A313: 45965 | B313: 1483.9 | C313: 1492.8 | D313: 1470.1 | E313: 1484.7 | F313: 1473.1 | G313: 1480.96 | H313: 1,00,07,806 | I313: 14,82,11,44,472.70 | J313: 2,18,103 | K313: -0.0078130262 | L313: -0.006431617 | M313: =VALUE(SUBSTITUTE(H313,",","")) -> 10007806
A314: 45967 | B314: 1484 | C314: 1501.6 | D314: 1476.2 | E314: 1473.1 | F314: 1496.1 | G314: 1494.08 | H314: 1,67,72,678 | I314: 25,05,96,56,533.30 | J314: 2,69,902 | K314: 0.015613332 | L314: -0.0034358623 | M314: =VALUE(SUBSTITUTE(H314,",","")) -> 16772678
...

Sheet TCS
A1: DATE | B1: OPEN | C1: HIGH | D1: LOW | E1: LTP | F1: CLOSE | G1: VWAP | H1: VOLUME | I1: VALUE | J1: NO. OF TRADES | K1: DAILY RETURN | L1: NIFTY RETURN
A2: 45509 | B2: 4239 | C2: 4239 | D2: 4110.5 | E2: 4160 | F2: 4155.05 | G2: 4165.25 | H2: 27,87,771 | I2: 11,61,17,60,562.20 | J2: 1,69,844 | M2: =VALUE(SUBSTITUTE(H2,",","")) -> 2787771
A3: 45510 | B3: 4170.95 | C3: 4258.25 | D3: 4160.8 | E3: 4175.1 | F3: 4171.2 | G3: 4193.98 | H3: 22,03,067 | I3: 9,23,96,08,320.05 | J3: 1,34,281 | K3: =(F3-F2)/F2 -> 0.0038868365 | L3: -0.0026210113 | M3: =VALUE(SUBSTITUTE(H3,",","")) -> 2203067
A4: 45511 | B4: 4228 | C4: 4244.95 | D4: 4180.3 | E4: 4201 | F4: 4200.45 | G4: 4201.58 | H4: 12,37,666 | I4: 5,20,01,50,778.85 | J4: 1,02,627 | K4: =(F4-F3)/F3 -> 0.0070123705 | L4: 0.012710195 | M4: =VALUE(SUBSTITUTE(H4,",","")) -> 1237666
A5: 45512 | B5: 4181 | C5: 4232 | D5: 4160 | E5: 4174 | F5: 4172.55 | G5: 4190.47 | H5: 24,41,283 | I5: 10,23,01,19,942.80 | J5: 1,20,490 | K5: =(F5-F4)/F4 -> -0.0066421455 | L5: -0.0074287478 | M5: =VALUE(SUBSTITUTE(H5,",","")) -> 2441283
A6: 45513 | B6: 4217 | C6: 4253.65 | D6: 4205.55 | E6: 4220 | F6: 4228.75 | G6: 4233.82 | H6: 13,02,536 | I6: 5,51,47,05,150.35 | J6: 79876 | K6: =(F6-F5)/F5 -> 0.013468982 | L6: 0.010386864 | M6: =VALUE(SUBSTITUTE(H6,",","")) -> 1302536
A7: 45516 | B7: 4230 | C7: 4239 | D7: 4186.35 | E7: 4193.1 | F7: 4195.65 | G7: 4210.62 | H7: 9,36,912 | I7: 3,94,49,78,151.60 | J7: 86028 | K7: =(F7-F6)/F6 -> -0.0078273722 | L7: -0.0008412845 | M7: =VALUE(SUBSTITUTE(H7,",","")) -> 936912
A8: 45517 | B8: 4213 | C8: 4234 | D8: 4183 | E8: 4197 | F8: 4196.95 | G8: 4209.09 | H8: 14,95,593 | I8: 6,29,50,91,175.55 | J8: 99105 | K8: =(F8-F7)/F7 -> 0.00030984472 | L8: -0.008543147 | M8: =VALUE(SUBSTITUTE(H8,",","")) -> 1495593
A9: 45518 | B9: 4209 | C9: 4306.2 | D9: 4188.15 | E9: 4293 | F9: 4295.25 | G9: 4265.75 | H9: 32,26,545 | I9: 13,76,36,19,690.80 | J9: 1,82,461 | K9: =(F9-F8)/F8 -> 0.023421771 | L9: 0.000196777 | M9: =VALUE(SUBSTITUTE(H9,",","")) -> 3226545
A10: 45520 | B10: 4350 | C10: 4427 | D10: 4325.1 | E10: 4414.2 | F10: 4416.05 | G10: 4395.48 | H10: 34,57,058 | I10: 15,19,54,30,172.75 | J10: 2,33,969 | K10: =(F10-F9)/F9 -> 0.028124091 | L10: 0.016459746 | M10: =VALUE(SUBSTITUTE(H10,",","")) -> 3457058
A11: 45523 | B11: 4421 | C11: 4494.25 | D11: 4390.35 | E11: 4490 | F11: 4490 | G11: 4459.62 | H11: 20,55,210 | I11: 9,16,54,57,457.55 | J11: 1,18,736 | K11: =(F11-F10)/F10 -> 0.016745734 | L11: 0.0012835584 | M11: =VALUE(SUBSTITUTE(H11,",","")) -> 2055210
A12: 45524 | B12: 4505 | C12: 4565 | D12: 4500 | E12: 4505 | F12: 4523.3 | G12: 4529.5 | H12: 22,12,298 | I12: 10,02,06,13,301.75 | J12: 1,28,019 | K12: =(F12-F11)/F11 -> 0.0074164811 | L12: 0.0051357912 | M12: =VALUE(SUBSTITUTE(H12,",","")) -> 2212298
A13: 45525 | B13: 4518 | C13: 4560 | D13: 4492.55 | E13: 4550 | F13: 4551.5 | G13: 4529.61 | H13: 18,96,990 | I13: 8,59,26,17,038.50 | J13: 1,15,023 | K13: =(F13-F12)/F12 -> 0.0062343864 | L13: 0.0028887985 | M13: =VALUE(SUBSTITUTE(H13,",","")) -> 1896990
A14: 45526 | B14: 4560 | C14: 4560.95 | D14: 4497.2 | E14: 4502 | F14: 4502 | G14: 4515.52 | H14: 18,29,872 | I14: 8,26,28,19,007.85 | J14: 1,14,303 | K14: =(F14-F13)/F13 -> -0.010875536 | L14: 0.0016673261 | M14: =VALUE(SUBSTITUTE(H14,",","")) -> 1829872
A15: 45527 | B15: 4500 | C15: 4506 | D15: 4455 | E15: 4473.05 | F15: 4463.9 | G15: 4469.04 | H15: 18,09,253 | I15: 8,08,56,19,687.40 | J15: 1,01,893 | K15: =(F15-F14)/F14 -> -0.0084629054 | L15: 0.00046954033 | M15: =VALUE(SUBSTITUTE(H15,",","")) -> 1809253
A16: 45530 | B16: 4489 | C16: 4552.15 | D16: 4485 | E16: 4506.6 | F16: 4502.45 | G16: 4517.26 | H16: 18,44,164 | I16: 8,33,05,71,610.15 | J16: 1,18,509 | K16: =(F16-F15)/F15 -> 0.0086359461 | L16: 0.0075514187 | M16: =VALUE(SUBSTITUTE(H16,",","")) -> 1844164
A17: 45531 | B17: 4505 | C17: 4510 | D17: 4486.8 | E17: 4491 | F17: 4497.15 | G17: 4496.77 | H17: 9,30,697 | I17: 4,18,51,34,647.00 | J17: 65265 | K17: =(F17-F16)/F16 -> -0.0011771369 | L17: 0.00028587879 | M17: =VALUE(SUBSTITUTE(H17,",","")) -> 930697
A18: 45532 | B18: 4498.75 | C18: 4562.5 | D18: 4457.3 | E18: 4513 | F18: 4506.05 | G18: 4515.24 | H18: 18,48,058 | I18: 8,34,44,30,539.80 | J18: 1,27,744 | K18: =(F18-F17)/F17 -> 0.0019790312 | L18: 0.0013830181 | M18: =VALUE(SUBSTITUTE(H18,",","")) -> 1848058
A19: 45533 | B19: 4460 | C19: 4556 | D19: 4460 | E19: 4507 | F19: 4511.8 | G19: 4515.71 | H19: 21,33,641 | I19: 9,63,48,99,513.20 | J19: 1,38,513 | K19: =(F19-F18)/F18 -> 0.0012760622 | L19: 0.0039756749 | M19: =VALUE(SUBSTITUTE(H19,",","")) -> 2133641
A20: 45534 | B20: 4500 | C20: 4592.25 | D20: 4487.8 | E20: 4562.7 | F20: 4553.75 | G20: 4545.75 | H20: 36,37,222 | I20: 16,53,39,15,087.45 | J20: 1,55,239 | K20: =(F20-F19)/F19 -> 0.0092978412 | L20: 0.0033377134 | M20: =VALUE(SUBSTITUTE(H20,",","")) -> 3637222
A21: 45537 | B21: 4576 | C21: 4588 | D21: 4512 | E21: 4526.4 | F21: 4521.05 | G21: 4545.25 | H21: 12,16,500 | I21: 5,52,92,99,899.10 | J21: 1,09,365 | K21: =(F21-F20)/F20 -> -0.0071808949 | L21: 0.0016959966 | M21: =VALUE(SUBSTITUTE(H21,",","")) -> 1216500
A22: 45538 | B22: 4521.05 | C22: 4555.9 | D22: 4495.9 | E22: 4512.65 | F22: 4512.35 | G22: 4523.6 | H22: 17,17,263 | I22: 7,76,82,15,760.70 | J22: 1,17,744 | K22: =(F22-F21)/F21 -> -0.0019243317 | L22: 4.5492846e-05 | M22: =VALUE(SUBSTITUTE(H22,",","")) -> 1717263
A23: 45539 | B23: 4476.95 | C23: 4487 | D23: 4436.7 | E23: 4484 | F23: 4479.25 | G23: 4468.96 | H23: 12,65,505 | I23: 5,65,54,96,454.35 | J23: 1,23,447 | K23: =(F23-F22)/F22 -> -0.0073354239 | L23: -0.0032100665 | M23: =VALUE(SUBSTITUTE(H23,",","")) -> 1265505
A24: 45540 | B24: 4481 | C24: 4499 | D24: 4454.15 | E24: 4490 | F24: 4475.95 | G24: 4469.15 | H24: 16,88,793 | I24: 7,54,74,77,632.90 | J24: 1,05,236 | K24: =(F24-F23)/F23 -> -0.00073673048 | L24: -0.0021270939 | M24: =VALUE(SUBSTITUTE(H24,",","")) -> 1688793
A25: 45541 | B25: 4473.95 | C25: 4518.95 | D25: 4440 | E25: 4460.5 | F25: 4456.75 | G25: 4466.8 | H25: 16,49,179 | I25: 7,36,65,46,120.25 | J25: 1,48,566 | K25: =(F25-F24)/F24 -> -0.0042895922 | L25: -0.011650381 | M25: =VALUE(SUBSTITUTE(H25,",","")) -> 1649179
A26: 45544 | B26: 4455 | C26: 4490.25 | D26: 4430.5 | E26: 4458 | F26: 4449.55 | G26: 4459.58 | H26: 11,84,938 | I26: 5,28,43,28,321.15 | J26: 92569 | K26: =(F26-F25)/F25 -> -0.001615527 | L26: 0.0033900487 | M26: =VALUE(SUBSTITUTE(H26,",","")) -> 1184938
A27: 45545 | B27: 4442.45 | C27: 4539.95 | D27: 4440.45 | E27: 4510 | F27: 4507.85 | G27: 4499.44 | H27: 13,85,591 | I27: 6,23,43,77,452.20 | J27: 1,25,535 | K27: =(F27-F26)/F26 -> 0.013102449 | L27: 0.0041986814 | M27: =VALUE(SUBSTITUTE(H27,",","")) -> 1385591
A28: 45546 | B28: 4521.45 | C28: 4549.35 | D28: 4471.25 | E28: 4495.5 | F28: 4479.35 | G28: 4504.96 | H28: 13,25,919 | I28: 5,97,32,12,660.05 | J28: 1,27,870 | K28: =(F28-F27)/F27 -> -0.0063223044 | L28: -0.0048979478 | M28: =VALUE(SUBSTITUTE(H28,",","")) -> 1325919
A29: 45547 | B29: 4510.25 | C29: 4532.6 | D29: 4431.3 | E29: 4495.3 | F29: 4517.7 | G29: 4485.01 | H29: 27,42,216 | I29: 12,29,88,52,603.60 | J29: 1,79,765 | K29: =(F29-F28)/F28 -> 0.00856151 | L29: 0.018879585 | M29: =VALUE(SUBSTITUTE(H29,",","")) -> 2742216
A30: 45548 | B30: 4530 | C30: 4547 | D30: 4505 | E30: 4521.75 | F30: 4522.6 | G30: 4526.87 | H30: 14,58,786 | I30: 6,60,37,40,972.90 | J30: 78892 | K30: =(F30-F29)/F29 -> 0.0010846227 | L30: -0.0012761482 | M30: =VALUE(SUBSTITUTE(H30,",","")) -> 1458786
A31: 45551 | B31: 4527 | C31: 4546.05 | D31: 4494.45 | E31: 4509 | F31: 4513.25 | G31: 4516.51 | H31: 11,55,120 | I31: 5,21,71,13,716.25 | J31: 61456 | K31: =(F31-F30)/F30 -> -0.0020673949 | L31: 0.0010746751 | M31: =VALUE(SUBSTITUTE(H31,",","")) -> 1155120
A32: 45552 | B32: 4513.25 | C32: 4535.8 | D32: 4466 | E32: 4511 | F32: 4505.65 | G32: 4505.75 | H32: 16,99,364 | I32: 7,65,69,02,882.20 | J32: 88562 | K32: =(F32-F31)/F31 -> -0.0016839306 | L32: 0.0013709558 | M32: =VALUE(SUBSTITUTE(H32,",","")) -> 1699364
A33: 45553 | B33: 4497.05 | C33: 4497.05 | D33: 4321 | E33: 4347.9 | F33: 4346.15 | G33: 4370.07 | H33: 29,61,779 | I33: 12,94,31,88,817.60 | J33: 2,44,673 | K33: =(F33-F32)/F32 -> -0.035399998 | L33: -0.0016129952 | M33: =VALUE(SUBSTITUTE(H33,",","")) -> 2961779
A34: 45554 | B34: 4390.05 | C34: 4422.2 | D34: 4281.8 | E34: 4307 | F34: 4296.15 | G34: 4321.08 | H34: 29,27,551 | I34: 12,65,01,87,150.25 | J34: 2,32,656 | K34: =(F34-F33)/F33 -> -0.011504435 | L34: 0.0015072377 | M34: =VALUE(SUBSTITUTE(H34,",","")) -> 2927551
A35: 45555 | B35: 4316.9 | C35: 4330.7 | D35: 4227.5 | E35: 4295 | F35: 4284.9 | G35: 4278.76 | H35: 54,47,908 | I35: 23,31,03,16,503.10 | J35: 2,91,115 | K35: =(F35-F34)/F34 -> -0.0026186237 | L35: 0.014760503 | M35: =VALUE(SUBSTITUTE(H35,",","")) -> 5447908
A36: 45558 | B36: 4300 | C36: 4309.4 | D36: 4253 | E36: 4266.05 | F36: 4268.5 | G36: 4270.4 | H36: 17,02,319 | I36: 7,26,95,88,108.95 | J36: 1,69,788 | K36: =(F36-F35)/F35 -> -0.0038273939 | L36: 0.0057423243 | M36: =VALUE(SUBSTITUTE(H36,",","")) -> 1702319
A37: 45559 | B37: 4251.65 | C37: 4291 | D37: 4240 | E37: 4282 | F37: 4271.3 | G37: 4265.03 | H37: 30,12,026 | I37: 12,84,63,72,402.70 | J37: 1,40,428 | K37: =(F37-F36)/F36 -> 0.00065596814 | L37: 5.2045083e-05 | M37: =VALUE(SUBSTITUTE(H37,",","")) -> 3012026
A38: 45560 | B38: 4252.35 | C38: 4289.6 | D38: 4240 | E38: 4275.35 | F38: 4274.75 | G38: 4263.61 | H38: 27,13,073 | I38: 11,56,74,83,701.95 | J38: 1,53,942 | K38: =(F38-F37)/F37 -> 0.00080771662 | L38: 0.0024575566 | M38: =VALUE(SUBSTITUTE(H38,",","")) -> 2713073
A39: 45561 | B39: 4260 | C39: 4316.8 | D39: 4260 | E39: 4295 | F39: 4292.5 | G39: 4288.28 | H39: 39,64,251 | I39: 16,99,98,20,745.85 | J39: 1,85,888 | K39: =(F39-F38)/F38 -> 0.0041522896 | L39: 0.0081486993 | M39: =VALUE(SUBSTITUTE(H39,",","")) -> 3964251
A40: 45562 | B40: 4335 | C40: 4378 | D40: 4300.05 | E40: 4305 | F40: 4308.7 | G40: 4327.38 | H40: 30,12,477 | I40: 13,03,61,44,375.45 | J40: 2,31,071 | K40: =(F40-F39)/F39 -> 0.0037740245 | L40: -0.0014151636 | M40: =VALUE(SUBSTITUTE(H40,",","")) -> 3012477
...

Sheet INFY
A1: DATE | B1: OPEN | C1: HIGH | D1: LOW | E1: PREV. CLOSE | F1: CLOSE | G1: VWAP | H1: VOLUME | I1: VALUE | J1: NO. OF TRADES | K1: DAILY RETURN | L1: NIFTY RETURN
A2: 45509 | B2: 1784.95 | C2: 1797.5 | D2: 1718.55 | E2: 1821.2 | F2: 1751.9 | G2: 1748.15 | H2: 1,07,36,703 | I2: 18,76,93,78,971.85 | J2: 3,57,150 | M2: =VALUE(SUBSTITUTE(H2,",","")) -> 10736703
A3: 45510 | B3: 1760.2 | C3: 1796.95 | D3: 1744.85 | E3: 1751.9 | F3: 1751.1 | G3: 1762.7 | H3: 76,90,163 | I3: 13,55,54,53,181.95 | J3: 2,29,956 | K3: =(F3-F2)/F2 -> -0.00045664707 | L3: -0.0026210113 | M3: =VALUE(SUBSTITUTE(H3,",","")) -> 7690163
A4: 45511 | B4: 1796 | C4: 1797.9 | D4: 1762.1 | E4: 1751.1 | F4: 1791.65 | G4: 1782.2 | H4: 50,94,329 | I4: 9,07,91,19,381.90 | J4: 1,89,924 | K4: =(F4-F3)/F3 -> 0.023156873 | L4: 0.012710195 | M4: =VALUE(SUBSTITUTE(H4,",","")) -> 5094329
A5: 45512 | B5: 1779.95 | C5: 1779.95 | D5: 1727.1 | E5: 1791.65 | F5: 1743.15 | G5: 1748.61 | H5: 62,27,910 | I5: 10,89,02,09,220.55 | J5: 2,37,457 | K5: =(F5-F4)/F4 -> -0.027070019 | L5: -0.0074287478 | M5: =VALUE(SUBSTITUTE(H5,",","")) -> 6227910
A6: 45513 | B6: 1771.25 | C6: 1780.75 | D6: 1756 | E6: 1743.15 | F6: 1770.75 | G6: 1766.78 | H6: 42,58,524 | I6: 7,52,38,90,127.90 | J6: 1,30,511 | K6: =(F6-F5)/F5 -> 0.015833405 | L6: 0.010386864 | M6: =VALUE(SUBSTITUTE(H6,",","")) -> 4258524
A7: 45516 | B7: 1773.05 | C7: 1803.5 | D7: 1768.1 | E7: 1770.75 | F7: 1797.4 | G7: 1793.12 | H7: 43,15,329 | I7: 7,73,79,16,018.35 | J7: 1,38,899 | K7: =(F7-F6)/F6 -> 0.01505012 | L7: -0.0008412845 | M7: =VALUE(SUBSTITUTE(H7,",","")) -> 4315329
A8: 45517 | B8: 1810 | C8: 1810 | D8: 1789.05 | E8: 1797.4 | F8: 1797.45 | G8: 1799.3 | H8: 41,76,918 | I8: 7,51,55,36,069.05 | J8: 1,52,390 | K8: =(F8-F7)/F7 -> 2.7817959e-05 | L8: -0.008543147 | M8: =VALUE(SUBSTITUTE(H8,",","")) -> 4176918
A9: 45518 | B9: 1802 | C9: 1825 | D9: 1797.45 | E9: 1797.45 | F9: 1823.25 | G9: 1813.72 | H9: 74,50,718 | I9: 13,51,35,04,750.80 | J9: 1,95,413 | K9: =(F9-F8)/F8 -> 0.014353668 | L9: 0.000196777 | M9: =VALUE(SUBSTITUTE(H9,",","")) -> 7450718
A10: 45520 | B10: 1850 | C10: 1861.85 | D10: 1829.5 | E10: 1823.25 | F10: 1858.95 | G10: 1844.85 | H10: 73,35,657 | I10: 13,53,31,80,793.15 | J10: 2,18,353 | K10: =(F10-F9)/F9 -> 0.01958042 | L10: 0.016459746 | M10: =VALUE(SUBSTITUTE(H10,",","")) -> 7335657
A11: 45523 | B11: 1860 | C11: 1867.55 | D11: 1849.2 | E11: 1858.95 | F11: 1864.8 | G11: 1862.3 | H11: 25,85,989 | I11: 4,81,58,90,949.80 | J11: 1,40,168 | K11: =(F11-F10)/F10 -> 0.0031469378 | L11: 0.0012835584 | M11: =VALUE(SUBSTITUTE(H11,",","")) -> 2585989
A12: 45524 | B12: 1880 | C12: 1885.7 | D12: 1868.2 | E12: 1864.8 | F12: 1872.2 | G12: 1875.2 | H12: 38,70,333 | I12: 7,25,76,35,525.75 | J12: 1,41,879 | K12: =(F12-F11)/F11 -> 0.003968254 | L12: 0.0051357912 | M12: =VALUE(SUBSTITUTE(H12,",","")) -> 3870333
A13: 45525 | B13: 1875.1 | C13: 1879 | D13: 1867.1 | E13: 1872.2 | F13: 1872.7 | G13: 1871.57 | H13: 19,66,902 | I13: 3,68,11,87,613.50 | J13: 1,16,979 | K13: =(F13-F12)/F12 -> 0.00026706548 | L13: 0.0028887985 | M13: =VALUE(SUBSTITUTE(H13,",","")) -> 1966902
A14: 45526 | B14: 1884 | C14: 1893.65 | D14: 1869.7 | E14: 1872.7 | F14: 1880.25 | G14: 1880.39 | H14: 43,00,287 | I14: 8,08,62,21,002.75 | J14: 1,85,241 | K14: =(F14-F13)/F13 -> 0.0040316121 | L14: 0.0016673261 | M14: =VALUE(SUBSTITUTE(H14,",","")) -> 4300287
... A30: 45548 | B30: 1950.45 | C30: 1958.6 | D30: 1935.65 | E30: 1950.45 | F30: 1944.1 | G30: 1948.85 | H30: 38,43,127 | I30: 7,48,96,65,426.75 | J30: 1,20,139 | K30: =(F30-F29)/F29 -> -0.0032556589 | L30: -0.0012761482 | M30: =VALUE(SUBSTITUTE(H30,",","")) -> 3843127
A31: 45551 | B31: 1945.75 | C31: 1952 | D31: 1933.05 | E31: 1944.1 | F31: 1950.25 | G31: 1943.67 | H31: 15,70,181 | I31: 3,05,19,12,524.40 | J31: 72563 | K31: =(F31-F30)/F30 -> 0.0031634175 | L31: 0.0010746751 | M31: =VALUE(SUBSTITUTE(H31,",","")) -> 1570181
A32: 45552 | B32: 1947.75 | C32: 1958.45 | D32: 1942.15 | E32: 1950.25 | F32: 1952.55 | G32: 1951.76 | H32: 27,93,127 | I32: 5,45,15,01,004.50 | J32: 1,42,203 | K32: =(F32-F31)/F31 -> 0.001179336 | L32: 0.0013709558 | M32: =VALUE(SUBSTITUTE(H32,",","")) -> 2793127
A33: 45553 | B33: 1938.75 | C33: 1938.75 | D33: 1881.3 | E33: 1952.55 | F33: 1892.15 | G33: 1898.2 | H33: 63,85,468 | I33: 12,12,08,91,191.90 | J33: 2,52,266 | K33: =(F33-F32)/F32 -> -0.030933907 | L33: -0.0016129952 | M33: =VALUE(SUBSTITUTE(H33,",","")) -> 6385468
A34: 45554 | B34: 1910.6 | C34: 1924.9 | D34: 1878.8 | E34: 1892.15 | F34: 1894.2 | G34: 1894.84 | H34: 79,76,570 | I34: 15,11,43,09,893.55 | J34: 2,19,801 | K34: =(F34-F33)/F33 -> 0.0010834236 | L34: 0.0015072377 | M34: =VALUE(SUBSTITUTE(H34,",","")) -> 7976570
A35: 45555 | B35: 1905 | C35: 1915 | D35: 1867.4 | E35: 1894.2 | F35: 1905.75 | G35: 1902.04 | H35: 1,52,42,974 | I35: 28,99,27,78,817.95 | J35: 3,46,786 | K35: =(F35-F34)/F34 -> 0.006097561 | L35: 0.014760503 | M35: =VALUE(SUBSTITUTE(H35,",","")) -> 15242974
A36: 45558 | B36: 1909 | C36: 1918.9 | D36: 1878.45 | E36: 1905.75 | F36: 1896.45 | G36: 1890.26 | H36: 36,36,672 | I36: 6,87,42,60,634.45 | J36: 1,33,793 | K36: =(F36-F35)/F35 -> -0.0048799685 | L36: 0.0057423243 | M36: =VALUE(SUBSTITUTE(H36,",","")) -> 3636672
A37: 45559 | B37: 1888 | C37: 1910.9 | D37: 1871.4 | E37: 1896.45 | F37: 1898.6 | G37: 1888.94 | H37: 72,77,616 | I37: 13,74,69,48,535.65 | J37: 1,81,532 | K37: =(F37-F36)/F36 -> 0.0011336972 | L37: 5.2045083e-05 | M37: =VALUE(SUBSTITUTE(H37,",","")) -> 7277616
A38: 45560 | B38: 1886.35 | C38: 1901.6 | D38: 1876.8 | E38: 1898.6 | F38: 1895.3 | G38: 1889.52 | H38: 42,68,341 | I38: 8,06,51,07,237.85 | J38: 1,73,033 | K38: =(F38-F37)/F37 -> -0.0017381228 | L38: 0.0024575566 | M38: =VALUE(SUBSTITUTE(H38,",","")) -> 4268341
A39: 45561 | B39: 1897.8 | C39: 1917.95 | D39: 1893 | E39: 1895.3 | F39: 1900.25 | G39: 1902.94 | H39: 89,52,803 | I39: 17,03,66,13,838.85 | J39: 2,04,902 | K39: =(F39-F38)/F38 -> 0.0026117237 | L39: 0.0081486993 | M39: =VALUE(SUBSTITUTE(H39,",","")) -> 8952803
A40: 45562 | B40: 1932.1 | C40: 1974.6 | D40: 1903.3 | E40: 1900.25 | F40: 1906.75 | G40: 1926.62 | H40: 1,49,08,931 | I40: 28,72,38,92,455.00 | J40: 3,01,305 | K40: =(F40-F39)/F39 -> 0.0034206026 | L40: -0.0014151636 | M40: =VALUE(SUBSTITUTE(H40,",","")) -> 14908931
A41: 45565 | B41: 1880 | C41: 1901.25 | D41: 1870.5 | E41: 1906.75 | F41: 1875.6 | G41: 1881.3 | H41: 69,86,955 | I41: 13,14,45,82,073.90 | J41: 2,25,929 | K41: =(F41-F40)/F40 -> -0.016336699 | L41: -0.014060915 | M41: =VALUE(SUBSTITUTE(H41,",","")) -> 6986955
A42: 45566 | B42: 1875 | C42: 1908.95 | D42: 1875 | E42: 1875.6 | F42: 1904.35 | G42: 1898.99 | H42: 40,29,072 | I42: 7,65,11,53,333.05 | J42: 1,53,975 | K42: =(F42-F41)/F41 -> 0.015328428 | L42: -0.00054047038 | M42: =VALUE(SUBSTITUTE(H42,",","")) -> 4029072
A43: 45568 | B43: 1889.5 | C43: 1911.85 | D43: 1881 | E43: 1904.35 | F43: 1893.4 | G43: 1895.02 | H43: 75,03,887 | I43: 14,22,00,32,273.75 | J43: 2,79,836 | K43: =(F43-F42)/F42 -> -0.0057499934 | L43: -0.021196345 | M43: =VALUE(SUBSTITUTE(H43,",","")) -> 7503887
... A63: 45596 | B63: 1787.9 | C63: 1787.9 | D63: 1746.5 | E63: 1802.1 | F63: 1757.25 | G63: 1759.11 | H63: 73,95,236 | I63: 13,00,90,50,347.40 | J63: 2,83,103 | K63: =(F63-F62)/F62 -> -0.024887631 | L63: -0.0055667736 | M63: =VALUE(SUBSTITUTE(H63,",","")) -> 7395236
A64: 45597 | B64: 1764.5 | C64: 1766 | D64: 1752.05 | E64: 1757.25 | F64: 1760.85 | G64: 1761.68 | H64: 3,71,966 | I64: 65,52,84,656.85 | J64: 29613 | K64: =(F64-F63)/F63 -> 0.0020486556 | L64: 0.0040900049 | M64: =VALUE(SUBSTITUTE(H64,",","")) -> 371966
A65: 45600 | B65: 1724.5 | C65: 1767 | D65: 1718 | E65: 1760.85 | F65: 1763.65 | G65: 1742.2 | H65: 73,36,722 | I65: 12,78,20,53,575.35 | J65: 2,37,541 | K65: =(F65-F64)/F64 -> 0.0015901411 | L65: -0.012713773 | M65: =VALUE(SUBSTITUTE(H65,",","")) -> 7336722
A66: 45601 | B66: 1760 | C66: 1768.45 | D66: 1745 | E66: 1763.65 | F66: 1754.2 | G66: 1754.19 | H66: 31,60,880 | I66: 5,54,47,81,198.40 | J66: 1,68,160 | K66: =(F66-F65)/F65 -> -0.005358206 | L66: 0.0090830098 | M66: =VALUE(SUBSTITUTE(H66,",","")) -> 3160880
A67: 45602 | B67: 1764 | C67: 1827.2 | D67: 1762.65 | E67: 1754.2 | F67: 1823.7 | G67: 1809.14 | H67: 1,04,21,494 | I67: 18,85,39,55,667.25 | J67: 3,05,870 | K67: =(F67-F66)/F66 -> 0.0396192 | L67: 0.011181871 | M67: =VALUE(SUBSTITUTE(H67,",","")) -> 10421494
A68: 45603 | B68: 1812.95 | C68: 1825.7 | D68: 1787 | E68: 1823.7 | F68: 1803.05 | G68: 1802.49 | H68: 45,50,965 | I68: 8,20,30,53,863.70 | J68: 2,74,916 | K68: =(F68-F67)/F67 -> -0.011323134 | L68: -0.011627978 | M68: =VALUE(SUBSTITUTE(H68,",","")) -> 4550965
A69: 45604 | B69: 1818 | C69: 1840.6 | D69: 1813.15 | E69: 1803.05 | F69: 1829.95 | G69: 1832.23 | H69: 42,10,960 | I69: 7,71,54,46,613.70 | J69: 1,99,379 | K69: =(F69-F68)/F68 -> 0.014919165 | L69: -0.0021136931 | M69: =VALUE(SUBSTITUTE(H69,",","")) -> 4210960
A70: 45607 | B70: 1829 | C70: 1868 | D70: 1822.55 | E70: 1829.95 | F70: 1860.1 | G70: 1855.73 | H70: 38,04,234 | I70: 7,05,96,43,882.45 | J70: 2,40,025 | K70: =(F70-F69)/F69 -> 0.01647586 | L70: -0.00028573558 | M70: =VALUE(SUBSTITUTE(H70,",","")) -> 3804234
A71: 45608 | B71: 1871.1 | C71: 1881 | D71: 1861 | E71: 1860.1 | F71: 1868.8 | G71: 1871.65 | H71: 50,12,450 | I71: 9,38,15,50,004.50 | J71: 1,82,346 | K71: =(F71-F70)/F70 -> 0.0046771679 | L71: -0.010680866 | M71: =VALUE(SUBSTITUTE(H71,",","")) -> 5012450
A72: 45609 | B72: 1861.1 | C72: 1873.2 | D72: 1856.3 | E72: 1868.8 | F72: 1868.4 | G72: 1866.77 | H72: 42,57,495 | I72: 7,94,77,52,333.85 | J72: 1,87,205 | K72: =(F72-F71)/F71 -> -0.0002140411 | L72: -0.013582627 | M72: =VALUE(SUBSTITUTE(H72,",","")) -> 4257495
A73: 45610 | B73: 1865.6 | C73: 1876 | D73: 1856 | E73: 1868.4 | F73: 1864.55 | G73: 1865.97 | H73: 43,11,431 | I73: 8,04,50,09,313.65 | J73: 2,06,703 | K73: =(F73-F72)/F72 -> -0.0020605866 | L73: -0.0011184662 | M73: =VALUE(SUBSTITUTE(H73,",","")) -> 4311431
A74: 45614 | B74: 1849.2 | C74: 1849.2 | D74: 1795 | E74: 1864.55 | F74: 1811.45 | G74: 1813.82 | H74: 48,39,244 | I74: 8,77,75,30,199.20 | J74: 2,07,559 | K74: =(F74-F73)/F73 -> -0.028478721 | L74: -0.0033527814 | M74: =VALUE(SUBSTITUTE(H74,",","")) -> 4839244
...

Sheet HDFCBANK
A1: DATE | B1: OPEN | C1: HIGH | D1: LOW | E1: PREV. CLOSE | F1: CLOSE | G1: VWAP | H1: VOLUME | I1: VALUE | J1: NO. OF TRADES | K1: DAILY RETURN | L1: NIFTY RETURN
A2: 45509 | B2: 1640.1 | C2: 1646 | D2: 1601 | E2: 1659.15 | F2: 1615.75 | G2: 1622.77 | H2: 2,06,66,817 | I2: 33,53,74,31,288.70 | J2: 4,64,696 | M2: =VALUE(SUBSTITUTE(H2,",","")) -> 20666817
A3: 45510 | B3: 1630 | C3: 1632.95 | D3: 1593.3 | E3: 1615.75 | F3: 1601.2 | G3: 1608.02 | H3: 2,25,58,025 | I3: 36,27,38,37,922.85 | J3: 3,88,854 | K3: =(F3-F2)/F2 -> -0.009005106 | L3: -0.0026210113 | M3: =VALUE(SUBSTITUTE(H3,",","")) -> 22558025
A4: 45511 | B4: 1617 | C4: 1630 | D4: 1602.2 | E4: 1601.2 | F4: 1623.5 | G4: 1617.23 | H4: 2,11,73,132 | I4: 34,24,18,47,264.50 | J4: 3,37,720 | K4: =(F4-F3)/F3 -> 0.013927055 | L4: 0.012710195 | M4: =VALUE(SUBSTITUTE(H4,",","")) -> 21173132
A5: 45512 | B5: 1624 | C5: 1653.3 | D5: 1619.25 | E5: 1623.5 | F5: 1642.7 | G5: 1638.73 | H5: 1,69,88,475 | I5: 27,83,95,62,575.60 | J5: 3,27,468 | K5: =(F5-F4)/F4 -> 0.011826301 | L5: -0.0074287478 | M5: =VALUE(SUBSTITUTE(H5,",","")) -> 16988475
A6: 45513 | B6: 1652 | C6: 1662.55 | D6: 1645.8 | E6: 1642.7 | F6: 1650.2 | G6: 1655.58 | H6: 1,33,22,309 | I6: 22,05,61,57,155.50 | J6: 2,91,916 | K6: =(F6-F5)/F5 -> 0.0045656541 | L6: 0.010386864 | M6: =VALUE(SUBSTITUTE(H6,",","")) -> 13322309
A7: 45516 | B7: 1652 | C7: 1675.95 | D7: 1647.35 | E7: 1650.2 | F7: 1660.1 | G7: 1664.63 | H7: 1,96,58,098 | I7: 32,72,35,06,965.00 | J7: 3,63,538 | K7: =(F7-F6)/F6 -> 0.0059992728 | L7: -0.0008412845 | M7: =VALUE(SUBSTITUTE(H7,",","")) -> 19658098
A8: 45517 | B8: 1628 | C8: 1632.4 | D8: 1601.15 | E8: 1660.1 | F8: 1603.2 | G8: 1613.32 | H8: 2,70,27,521 | I8: 43,60,41,63,966.10 | J8: 6,01,558 | K8: =(F8-F7)/F7 -> -0.034275044 | L8: -0.008543147 | M8: =VALUE(SUBSTITUTE(H8,",","")) -> 27027521
A9: 45518 | B9: 1606.5 | C9: 1613.7 | D9: 1603.2 | E9: 1603.2 | F9: 1607.8 | G9: 1607.97 | H9: 1,61,67,214 | I9: 25,99,64,12,110.40 | J9: 2,59,067 | K9: =(F9-F8)/F8 -> 0.0028692615 | L9: 0.000196777 | M9: =VALUE(SUBSTITUTE(H9,",","")) -> 16167214
A10: 45520 | B10: 1628.5 | C10: 1634.15 | D10: 1611 | E10: 1607.8 | F10: 1632.1 | G10: 1624.71 | H10: 1,39,24,623 | I10: 22,62,34,79,529.55 | J10: 3,02,506 | K10: =(F10-F9)/F9 -> 0.01511382 | L10: 0.016459746 | M10: =VALUE(SUBSTITUTE(H10,",","")) -> 13924623
A11: 45523 | B11: 1637.65 | C11: 1637.65 | D11: 1623.7 | E11: 1632.1 | F11: 1631.55 | G11: 1628.46 | H11: 97,51,082 | I11: 15,87,92,78,800.80 | J11: 1,66,314 | K11: =(F11-F10)/F10 -> -0.00033698916 | L11: 0.0012835584 | M11: =VALUE(SUBSTITUTE(H11,",","")) -> 9751082
A12: 45524 | B12: 1627.45 | C12: 1646 | D12: 1627.45 | E12: 1631.55 | F12: 1637.7 | G12: 1639.14 | H12: 1,55,67,247 | I12: 25,51,69,52,644.85 | J12: 2,40,802 | K12: =(F12-F11)/F11 -> 0.0037694217 | L12: 0.0051357912 | M12: =VALUE(SUBSTITUTE(H12,",","")) -> 15567247
A13: 45525 | B13: 1628.1 | C13: 1634.55 | D13: 1617.8 | E13: 1637.7 | F13: 1625.8 | G13: 1624.85 | H13: 2,38,15,452 | I13: 38,69,65,27,016.25 | J13: 3,23,415 | K13: =(F13-F12)/F12 -> -0.0072662881 | L13: 0.0028887985 | M13: =VALUE(SUBSTITUTE(H13,",","")) -> 23815452
A14: 45526 | B14: 1632 | C14: 1638.3 | D14: 1628 | E14: 1625.8 | F14: 1631.3 | G14: 1632.58 | H14: 1,06,50,319 | I14: 17,38,75,21,802.75 | J14: 2,72,441 | K14: =(F14-F13)/F13 -> 0.0033829499 | L14: 0.0016673261 | M14: =VALUE(SUBSTITUTE(H14,",","")) -> 10650319
... A63: 45596 | B63: 1728 | C63: 1738.9 | D63: 1719.4 | E63: 1734.6 | F63: 1735.7 | G63: 1731.49 | H63: 1,14,47,956 | I63: 19,82,20,46,508.90 | J63: 2,77,300 | K63: =(F63-F62)/F62 -> 0.00063415197 | L63: -0.0055667736 | M63: =VALUE(SUBSTITUTE(H63,",","")) -> 11447956
A64: 45597 | B64: 1733 | C64: 1744.1 | D64: 1726.1 | E64: 1735.7 | F64: 1737.3 | G64: 1738.79 | H64: 8,79,846 | I64: 1,52,98,70,165.60 | J64: 69860 | K64: =(F64-F63)/F63 -> 0.00092181829 | L64: 0.0040900049 | M64: =VALUE(SUBSTITUTE(H64,",","")) -> 879846
A65: 45600 | B65: 1745 | C65: 1745 | D65: 1710.9 | E65: 1737.3 | F65: 1714.1 | G65: 1723.47 | H65: 1,40,44,624 | I65: 24,20,55,13,156.95 | J65: 3,42,162 | K65: =(F65-F64)/F64 -> -0.013354055 | L65: -0.012713773 | M65: =VALUE(SUBSTITUTE(H65,",","")) -> 14044624
A66: 45601 | B66: 1703 | C66: 1762.7 | D66: 1697.9 | E66: 1714.1 | F66: 1757.85 | G66: 1736.4 | H66: 2,21,16,203 | I66: 38,40,25,43,188.05 | J66: 3,62,395 | K66: =(F66-F65)/F65 -> 0.025523598 | L66: 0.0090830098 | M66: =VALUE(SUBSTITUTE(H66,",","")) -> 22116203
A67: 45602 | B67: 1771.5 | C67: 1771.5 | D67: 1745.35 | E67: 1757.85 | F67: 1755.25 | G67: 1753.58 | H67: 1,38,93,955 | I67: 24,36,42,01,740.05 | J67: 2,49,677 | K67: =(F67-F66)/F66 -> -0.0014790796 | L67: 0.011181871 | M67: =VALUE(SUBSTITUTE(H67,",","")) -> 13893955
A68: 45603 | B68: 1744.3 | C68: 1760.95 | D68: 1738 | E68: 1755.25 | F68: 1746.55 | G68: 1746.6 | H68: 94,47,728 | I68: 16,50,13,84,112.80 | J68: 3,15,964 | K68: =(F68-F67)/F67 -> -0.0049565589 | L68: -0.011627978 | M68: =VALUE(SUBSTITUTE(H68,",","")) -> 9447728
A69: 45604 | B69: 1752 | C69: 1761.8 | D69: 1745.85 | E69: 1746.55 | F69: 1754.45 | G69: 1754.62 | H69: 99,51,493 | I69: 17,46,10,70,459.45 | J69: 2,53,333 | K69: =(F69-F68)/F68 -> 0.0045232029 | L69: -0.0021136931 | M69: =VALUE(SUBSTITUTE(H69,",","")) -> 9951493
A70: 45607 | B70: 1754.55 | C70: 1782.8 | D70: 1751.2 | E70: 1754.45 | F70: 1766.3 | G70: 1768.85 | H70: 1,22,82,681 | I70: 21,72,62,35,735.65 | J70: 3,66,875 | K70: =(F70-F69)/F69 -> 0.0067542535 | L70: -0.00028573558 | M70: =VALUE(SUBSTITUTE(H70,",","")) -> 12282681
A71: 45608 | B71: 1772 | C71: 1775 | D71: 1708.65 | E71: 1766.3 | F71: 1718.2 | G71: 1731.71 | H71: 1,56,97,703 | I71: 27,18,38,31,491.15 | J71: 4,10,691 | K71: =(F71-F70)/F70 -> -0.027232067 | L71: -0.010680866 | M71: =VALUE(SUBSTITUTE(H71,",","")) -> 15697703
A72: 45609 | B72: 1716.75 | C72: 1729.4 | D72: 1673 | E72: 1718.2 | F72: 1681.35 | G72: 1699.7 | H72: 1,78,64,250 | I72: 30,36,39,47,641.30 | J72: 3,84,592 | K72: =(F72-F71)/F71 -> -0.021446863 | L72: -0.013582627 | M72: =VALUE(SUBSTITUTE(H72,",","")) -> 17864250
A73: 45610 | B73: 1673.1 | C73: 1704.85 | D73: 1672.1 | E73: 1681.35 | F73: 1692.75 | G73: 1692.96 | H73: 1,35,73,235 | I73: 22,97,89,07,908.45 | J73: 3,31,159 | K73: =(F73-F72)/F72 -> 0.0067802659 | L73: -0.0011184662 | M73: =VALUE(SUBSTITUTE(H73,",","")) -> 13573235
A74: 45614 | B74: 1700 | C74: 1718.9 | D74: 1695 | E74: 1692.75 | F74: 1705.1 | G74: 1707.94 | H74: 1,35,40,984 | I74: 23,12,71,23,855.10 | J74: 2,91,631 | K74: =(F74-F73)/F73 -> 0.0072958204 | L74: -0.0033527814 | M74: =VALUE(SUBSTITUTE(H74,",","")) -> 13540984
A75: 45615 | B75: 1714 | C75: 1753.75 | D75: 1702.7 | E75: 1705.1 | F75: 1742.25 | G75: 1739.1 | H75: 2,54,90,636 | I75: 44,33,08,62,947.85 | J75: 4,58,303 | K75: =(F75-F74)/F74 -> 0.021787578 | L75: 0.0027586148 | M75: =VALUE(SUBSTITUTE(H75,",","")) -> 25490636
A76: 45617 | B76: 1749.4 | C76: 1759 | D76: 1734.2 | E76: 1742.25 | F76: 1741.2 | G76: 1743.63 | H76: 1,78,58,256 | I76: 31,13,81,62,734.40 | J76: 3,68,837 | K76: =(F76-F75)/F75 -> -0.00060266896 | L76: -0.0071688245 | M76: =VALUE(SUBSTITUTE(H76,",","")) -> 17858256
... A126: 45688 | B126: 1687.25 | C126: 1704.7 | D126: 1683.95 | E126: 1691.5 | F126: 1698.75 | G126: 1696.52 | H126: 79,10,843 | I126: 13,42,08,73,179.40 | J126: 2,15,938 | K126: =(F126-F125)/F125 -> 0.0042861366 | L126: 0.011135723 | M126: =VALUE(SUBSTITUTE(H126,",","")) -> 7910843
A127: 45689 | B127: 1697.5 | C127: 1713 | D127: 1676.05 | E127: 1698.75 | F127: 1690.95 | G127: 1694.22 | H127: 27,93,764 | I127: 4,73,32,38,897.95 | J127: 88839 | K127: =(F127-F126)/F126 -> -0.0045916115 | L127: -0.0011166221 | M127: =VALUE(SUBSTITUTE(H127,",","")) -> 2793764
A128: 45691 | B128: 1670 | C128: 1686.8 | D128: 1663.45 | E128: 1690.95 | F128: 1678 | G128: 1679.49 | H128: 1,01,38,270 | I128: 17,02,70,93,333.70 | J128: 2,30,780 | K128: =(F128-F127)/F127 -> -0.0076584169 | L128: -0.0051571087 | M128: =VALUE(SUBSTITUTE(H128,",","")) -> 10138270
A129: 45692 | B129: 1688.7 | C129: 1725.8 | D129: 1680.05 | E129: 1678 | F129: 1720.9 | G129: 1710.93 | H129: 1,43,08,251 | I129: 24,48,03,95,914.25 | J129: 3,42,091 | K129: =(F129-F128)/F128 -> 0.02556615 | L129: 0.016189341 | M129: =VALUE(SUBSTITUTE(H129,",","")) -> 14308251
A130: 45693 | B130: 1733 | C130: 1744.2 | D130: 1718.9 | E130: 1720.9 | F130: 1737.8 | G130: 1733.84 | H130: 1,18,37,753 | I130: 20,52,47,85,237.35 | J130: 2,75,185 | K130: =(F130-F129)/F129 -> 0.0098204428 | L130: -0.00180924 | M130: =VALUE(SUBSTITUTE(H130,",","")) -> 11837753
A131: 45694 | B131: 1735.5 | C131: 1749 | D131: 1724 | E131: 1737.8 | F131: 1743.85 | G131: 1735.75 | H131: 1,33,80,358 | I131: 23,22,50,08,521.55 | J131: 2,25,108 | K131: =(F131-F130)/F130 -> 0.0034814133 | L131: -0.0039225533 | M131: =VALUE(SUBSTITUTE(H131,",","")) -> 13380358
A132: 45695 | B132: 1750 | C132: 1767 | D132: 1725 | E132: 1743.85 | F132: 1732.75 | G132: 1744.99 | H132: 1,17,54,800 | I132: 20,51,20,07,682.55 | J132: 3,26,327 | K132: =(F132-F131)/F131 -> -0.0063652264 | L132: -0.001838722 | M132: =VALUE(SUBSTITUTE(H132,",","")) -> 11754800
A133: 45698 | B133: 1717.3 | C133: 1723.45 | D133: 1708.5 | E133: 1732.75 | F133: 1715.75 | G133: 1715.57 | H133: 85,97,975 | I133: 14,75,03,90,095.15 | J133: 1,75,150 | K133: =(F133-F132)/F132 -> -0.0098109941 | L133: -0.00757005 | M133: =VALUE(SUBSTITUTE(H133,",","")) -> 8597975
A134: 45699 | B134: 1703 | C134: 1711 | D134: 1688.7 | E134: 1715.75 | F134: 1701.4 | G134: 1700.06 | H134: 1,13,62,352 | I134: 19,31,66,30,388.15 | J134: 1,82,730 | K134: =(F134-F133)/F133 -> -0.0083636893 | L134: -0.013249735 | M134: =VALUE(SUBSTITUTE(H134,",","")) -> 11362352
A135: 45700 | B135: 1693 | C135: 1712 | D135: 1681.2 | E135: 1701.4 | F135: 1706.8 | G135: 1696.59 | H135: 1,14,04,785 | I135: 19,34,92,71,431.55 | J135: 2,86,053 | K135: =(F135-F134)/F134 -> 0.0031738568 | L135: -0.0011507555 | M135: =VALUE(SUBSTITUTE(H135,",","")) -> 11404785
A136: 45701 | B136: 1699 | C136: 1714.25 | D136: 1693.55 | E136: 1706.8 | F136: 1697.7 | G136: 1702.88 | H136: 63,01,217 | I136: 10,73,02,16,799.15 | J136: 2,00,278 | K136: =(F136-F135)/F135 -> -0.0053316147 | L136: -0.00060099153 | M136: =VALUE(SUBSTITUTE(H136,",","")) -> 6301217
A137: 45702 | B137: 1701.9 | C137: 1701.9 | D137: 1680 | E137: 1697.7 | F137: 1694.85 | G137: 1690.46 | H137: 99,79,946 | I137: 16,87,06,60,139.45 | J137: 3,09,031 | K137: =(F137-F136)/F136 -> -0.0016787418 | L137: -0.0044352493 | M137: =VALUE(SUBSTITUTE(H137,",","")) -> 9979946
...

Sheet ICICIBANK
A1: DATE | B1: OPEN | C1: HIGH | D1: LOW | E1: PREV. CLOSE | F1: CLOSE | G1: VWAP | H1: VOLUME | I1: VALUE | J1: NO. OF TRADES | K1: DAILY RETURN | L1: NIFTY RETURN
A2: 45509 | B2: 1182 | C2: 1188.9 | D2: 1167 | E2: 1196.55 | F2: 1172.6 | G2: 1173.69 | H2: 1,43,06,771 | I2: 16,79,16,69,195.40 | J2: 3,03,083 | M2: =VALUE(SUBSTITUTE(H2,",","")) -> 14306771
A3: 45510 | B3: 1175 | C3: 1187.7 | D3: 1161.5 | E3: 1172.6 | F3: 1166.85 | G3: 1169.06 | H3: 1,35,75,619 | I3: 15,87,07,78,423.20 | J3: 2,69,178 | K3: =(F3-F2)/F2 -> -0.004903633 | L3: -0.0026210113 | M3: =VALUE(SUBSTITUTE(H3,",","")) -> 13575619
A4: 45511 | B4: 1178.95 | C4: 1179.8 | D4: 1161.6 | E4: 1166.85 | F4: 1172.45 | G4: 1170.37 | H4: 1,57,53,644 | I4: 18,43,75,24,153.20 | J4: 2,68,848 | K4: =(F4-F3)/F3 -> 0.0047992458 | L4: 0.012710195 | M4: =VALUE(SUBSTITUTE(H4,",","")) -> 15753644
A5: 45512 | B5: 1166.95 | C5: 1174.4 | D5: 1158.9 | E5: 1172.45 | F5: 1164.6 | G5: 1166.37 | H5: 1,08,06,438 | I5: 12,60,42,62,739.90 | J5: 2,40,108 | K5: =(F5-F4)/F4 -> -0.0066953815 | L5: -0.0074287478 | M5: =VALUE(SUBSTITUTE(H5,",","")) -> 10806438
A6: 45513 | B6: 1176.55 | C6: 1180.95 | D6: 1169 | E6: 1164.6 | F6: 1171.6 | G6: 1173.65 | H6: 86,87,307 | I6: 10,19,58,33,284.65 | J6: 1,61,291 | K6: =(F6-F5)/F5 -> 0.0060106474 | L6: 0.010386864 | M6: =VALUE(SUBSTITUTE(H6,",","")) -> 8687307
A7: 45516 | B7: 1171 | C7: 1178.25 | D7: 1156 | E7: 1171.6 | F7: 1172.8 | G7: 1170.54 | H7: 1,08,60,455 | I7: 12,71,26,20,911.40 | J7: 2,06,013 | K7: =(F7-F6)/F6 -> 0.0010242404 | L7: -0.0008412845 | M7: =VALUE(SUBSTITUTE(H7,",","")) -> 10860455
A8: 45517 | B8: 1183.2 | C8: 1189.25 | D8: 1163.6 | E8: 1172.8 | F8: 1168.35 | G8: 1172.48 | H8: 1,31,17,927 | I8: 15,38,04,95,808.30 | J8: 2,60,022 | K8: =(F8-F7)/F7 -> -0.0037943383 | L8: -0.008543147 | M8: =VALUE(SUBSTITUTE(H8,",","")) -> 13117927
A9: 45518 | B9: 1167 | C9: 1170.05 | D9: 1153 | E9: 1168.35 | F9: 1161.65 | G9: 1159.56 | H9: 1,34,31,801 | I9: 15,57,50,00,780.50 | J9: 2,32,399 | K9: =(F9-F8)/F8 -> -0.005734583 | L9: 0.000196777 | M9: =VALUE(SUBSTITUTE(H9,",","")) -> 13431801
A10: 45520 | B10: 1170 | C10: 1193 | D10: 1165.65 | E10: 1161.65 | F10: 1187.25 | G10: 1181.45 | H10: 1,09,61,370 | I10: 12,95,03,02,290.60 | J10: 2,33,289 | K10: =(F10-F9)/F9 -> 0.022037619 | L10: 0.016459746 | M10: =VALUE(SUBSTITUTE(H10,",","")) -> 10961370
A11: 45523 | B11: 1191 | C11: 1195.75 | D11: 1173.3 | E11: 1187.25 | F11: 1175.9 | G11: 1181.33 | H11: 66,86,394 | I11: 7,89,88,45,446.25 | J11: 1,23,110 | K11: =(F11-F10)/F10 -> -0.0095599073 | L11: 0.0012835584 | M11: =VALUE(SUBSTITUTE(H11,",","")) -> 6686394
A12: 45524 | B12: 1174.2 | C12: 1189.8 | D12: 1170 | E12: 1175.9 | F12: 1179.45 | G12: 1181.26 | H12: 1,04,27,061 | I12: 12,31,71,05,974.95 | J12: 1,79,266 | K12: =(F12-F11)/F11 -> 0.0030189642 | L12: 0.0051357912 | M12: =VALUE(SUBSTITUTE(H12,",","")) -> 10427061
A13: 45525 | B13: 1177 | C13: 1178.65 | D13: 1165.1 | E13: 1179.45 | F13: 1174.85 | G13: 1172.27 | H13: 1,72,34,142 | I13: 20,20,31,11,541.65 | J13: 2,32,318 | K13: =(F13-F12)/F12 -> -0.0039001229 | L13: 0.0028887985 | M13: =VALUE(SUBSTITUTE(H13,",","")) -> 17234142
A14: 45526 | B14: 1182 | C14: 1192.6 | D14: 1176.6 | E14: 1174.85 | F14: 1191.1 | G14: 1187.45 | H14: 85,64,142 | I14: 10,16,94,62,494.05 | J14: 2,48,029 | K14: =(F14-F13)/F13 -> 0.013831553 | L14: 0.0016673261 | M14: =VALUE(SUBSTITUTE(H14,",","")) -> 8564142
... A63: 45596 | B63: 1307.25 | C63: 1318.95 | D63: 1288.55 | E63: 1312.15 | F63: 1292.25 | G63: 1296.28 | H63: 2,34,97,314 | I63: 30,45,90,66,088.40 | J63: 2,50,950 | K63: =(F63-F62)/F62 -> -0.015165949 | L63: -0.0055667736 | M63: =VALUE(SUBSTITUTE(H63,",","")) -> 23497314
A64: 45597 | B64: 1289.95 | C64: 1296.2 | D64: 1286.25 | E64: 1292.25 | F64: 1291.8 | G64: 1292.11 | H64: 10,07,022 | I64: 1,30,11,80,367.65 | J64: 40161 | K64: =(F64-F63)/F63 -> -0.00034822983 | L64: 0.0040900049 | M64: =VALUE(SUBSTITUTE(H64,",","")) -> 1007022
A65: 45600 | B65: 1290.1 | C65: 1291.8 | D65: 1270.05 | E65: 1291.8 | F65: 1277.2 | G65: 1276.5 | H65: 1,43,09,121 | I65: 18,26,56,49,923.80 | J65: 2,68,956 | K65: =(F65-F64)/F64 -> -0.011302059 | L65: -0.012713773 | M65: =VALUE(SUBSTITUTE(H65,",","")) -> 14309121
A66: 45601 | B66: 1273 | C66: 1301.3 | D66: 1263.1 | E66: 1277.2 | F66: 1296.7 | G66: 1284.33 | H66: 1,64,31,920 | I66: 21,10,40,80,468.90 | J66: 2,62,702 | K66: =(F66-F65)/F65 -> 0.015267773 | L66: 0.0090830098 | M66: =VALUE(SUBSTITUTE(H66,",","")) -> 16431920
A67: 45602 | B67: 1300.25 | C67: 1315 | D67: 1292.7 | E67: 1296.7 | F67: 1302.35 | G67: 1306.97 | H67: 1,20,37,405 | I67: 15,73,25,82,044.35 | J67: 2,01,411 | K67: =(F67-F66)/F66 -> 0.0043572145 | L67: 0.011181871 | M67: =VALUE(SUBSTITUTE(H67,",","")) -> 12037405
A68: 45603 | B68: 1297.15 | C68: 1302.8 | D68: 1275.25 | E68: 1302.35 | F68: 1278.7 | G68: 1282.48 | H68: 99,09,035 | I68: 12,70,81,18,911.40 | J68: 1,85,720 | K68: =(F68-F67)/F67 -> -0.018159481 | L68: -0.011627978 | M68: =VALUE(SUBSTITUTE(H68,",","")) -> 9909035
A69: 45604 | B69: 1270 | C69: 1275 | D69: 1252.7 | E69: 1278.7 | F69: 1258.85 | G69: 1260.33 | H69: 1,11,95,808 | I69: 14,11,04,19,237.85 | J69: 2,33,807 | K69: =(F69-F68)/F68 -> -0.015523579 | L69: -0.0021136931 | M69: =VALUE(SUBSTITUTE(H69,",","")) -> 11195808
A70: 45607 | B70: 1262 | C70: 1275.9 | D70: 1246.65 | E70: 1258.85 | F70: 1269.3 | G70: 1266.04 | H70: 83,87,780 | I70: 10,61,92,76,125.00 | J70: 1,93,310 | K70: =(F70-F69)/F69 -> 0.0083012273 | L70: -0.00028573558 | M70: =VALUE(SUBSTITUTE(H70,",","")) -> 8387780
A71: 45608 | B71: 1276.15 | C71: 1295 | D71: 1264.5 | E71: 1269.3 | F71: 1270.6 | G71: 1276.01 | H71: 1,34,86,168 | I71: 17,20,84,86,809.70 | J71: 2,51,685 | K71: =(F71-F70)/F70 -> 0.0010241866 | L71: -0.010680866 | M71: =VALUE(SUBSTITUTE(H71,",","")) -> 13486168
A72: 45609 | B72: 1270.6 | C72: 1276.25 | D72: 1250 | E72: 1270.6 | F72: 1253.7 | G72: 1261.05 | H72: 1,22,60,404 | I72: 15,46,09,65,858.00 | J72: 2,58,070 | K72: =(F72-F71)/F71 -> -0.013300803 | L72: -0.013582627 | M72: =VALUE(SUBSTITUTE(H72,",","")) -> 12260404
A73: 45610 | B73: 1253.75 | C73: 1267.7 | D73: 1243.05 | E73: 1253.7 | F73: 1256.95 | G73: 1255.26 | H73: 95,06,892 | I73: 11,93,35,98,279.70 | J73: 2,24,597 | K73: =(F73-F72)/F72 -> 0.0025923267 | L73: -0.0011184662 | M73: =VALUE(SUBSTITUTE(H73,",","")) -> 9506892
A74: 45614 | B74: 1260 | C74: 1262.6 | D74: 1249.4 | E74: 1256.95 | F74: 1253.45 | G74: 1254.62 | H74: 61,95,554 | I74: 7,77,30,53,428.25 | J74: 2,04,301 | K74: =(F74-F73)/F73 -> -0.0027845181 | L74: -0.0033527814 | M74: =VALUE(SUBSTITUTE(H74,",","")) -> 6195554
A75: 45615 | B75: 1257.05 | C75: 1261 | D75: 1240.85 | E75: 1253.45 | F75: 1249.1 | G75: 1251.54 | H75: 1,15,37,317 | I75: 14,43,94,01,407.20 | J75: 2,33,269 | K75: =(F75-F74)/F74 -> -0.0034704216 | L75: 0.0027586148 | M75: =VALUE(SUBSTITUTE(H75,",","")) -> 11537317
A76: 45617 | B76: 1248.55 | C76: 1256.9 | D76: 1232.55 | E76: 1249.1 | F76: 1250.55 | G76: 1247.38 | H76: 95,93,870 | I76: 11,96,71,89,179.00 | J76: 2,09,109 | K76: =(F76-F75)/F75 -> 0.0011608358 | L76: -0.0071688245 | M76: =VALUE(SUBSTITUTE(H76,",","")) -> 9593870
... A126: 45688 | B126: 1254.5 | C126: 1256 | D126: 1239.1 | E126: 1255.6 | F126: 1252.8 | G126: 1247.43 | H126: 1,01,95,417 | I126: 12,71,80,79,791.90 | J126: 2,09,906 | K126: =(F126-F125)/F125 -> -0.0022300096 | L126: 0.011135723 | M126: =VALUE(SUBSTITUTE(H126,",","")) -> 10195417
A127: 45689 | B127: 1251.15 | C127: 1261.35 | D127: 1233.8 | E127: 1252.8 | F127: 1255.55 | G127: 1250.34 | H127: 30,11,914 | I127: 3,76,59,27,780.55 | J127: 91971 | K127: =(F127-F126)/F126 -> 0.002195083 | L127: -0.0011166221 | M127: =VALUE(SUBSTITUTE(H127,",","")) -> 3011914
A128: 45691 | B128: 1246.85 | C128: 1260 | D128: 1237.8 | E128: 1255.55 | F128: 1253 | G128: 1250.06 | H128: 61,76,831 | I128: 7,72,14,38,599.85 | J128: 1,65,087 | K128: =(F128-F127)/F127 -> -0.0020309824 | L128: -0.0051571087 | M128: =VALUE(SUBSTITUTE(H128,",","")) -> 6176831
A129: 45692 | B129: 1262.8 | C129: 1280.5 | D129: 1260 | E129: 1253 | F129: 1268.2 | G129: 1270.45 | H129: 1,48,39,077 | I129: 18,85,23,69,674.65 | J129: 2,59,371 | K129: =(F129-F128)/F128 -> 0.012130886 | L129: 0.016189341 | M129: =VALUE(SUBSTITUTE(H129,",","")) -> 14839077
A130: 45693 | B130: 1270.2 | C130: 1277.75 | D130: 1265.15 | E130: 1268.2 | F130: 1267.7 | G130: 1270.65 | H130: 68,40,709 | I130: 8,69,21,68,613.10 | J130: 1,83,398 | K130: =(F130-F129)/F129 -> -0.00039425958 | L130: -0.00180924 | M130: =VALUE(SUBSTITUTE(H130,",","")) -> 6840709
A131: 45694 | B131: 1275 | C131: 1279 | D131: 1263.2 | E131: 1267.7 | F131: 1272.4 | G131: 1270.57 | H131: 83,96,554 | I131: 10,66,84,40,486.05 | J131: 2,26,596 | K131: =(F131-F130)/F130 -> 0.0037075018 | L131: -0.0039225533 | M131: =VALUE(SUBSTITUTE(H131,",","")) -> 8396554
A132: 45695 | B132: 1272 | C132: 1275 | D132: 1249.55 | E132: 1272.4 | F132: 1256.9 | G132: 1258.99 | H132: 73,82,039 | I132: 9,29,38,77,445.05 | J132: 1,91,355 | K132: =(F132-F131)/F131 -> -0.012181704 | L132: -0.001838722 | M132: =VALUE(SUBSTITUTE(H132,",","")) -> 7382039
A133: 45698 | B133: 1257.2 | C133: 1265 | D133: 1249.35 | E133: 1256.9 | F133: 1262.6 | G133: 1257.56 | H133: 57,40,361 | I133: 7,21,88,36,541.20 | J133: 1,80,650 | K133: =(F133-F132)/F132 -> 0.004534967 | L133: -0.00757005 | M133: =VALUE(SUBSTITUTE(H133,",","")) -> 5740361
A134: 45699 | B134: 1255.85 | C134: 1261.85 | D134: 1248.4 | E134: 1262.6 | F134: 1252.75 | G134: 1254.67 | H134: 65,86,627 | I134: 8,26,40,43,638.70 | J134: 1,74,408 | K134: =(F134-F133)/F133 -> -0.0078013623 | L134: -0.013249735 | M134: =VALUE(SUBSTITUTE(H134,",","")) -> 6586627
A135: 45700 | B135: 1257.2 | C135: 1269.75 | D135: 1244.65 | E135: 1252.75 | F135: 1251.8 | G135: 1252.33 | H135: 88,09,352 | I135: 11,03,22,00,057.65 | J135: 3,20,587 | K135: =(F135-F134)/F134 -> -0.00075833167 | L135: -0.0011507555 | M135: =VALUE(SUBSTITUTE(H135,",","")) -> 8809352
A136: 45701 | B136: 1252.55 | C136: 1266 | D136: 1245.9 | E136: 1251.8 | F136: 1248.9 | G136: 1254.61 | H136: 72,63,785 | I136: 9,11,32,47,793.40 | J136: 2,61,567 | K136: =(F136-F135)/F135 -> -0.002316664 | L136: -0.00060099153 | M136: =VALUE(SUBSTITUTE(H136,",","")) -> 7263785
A137: 45702 | B137: 1252.1 | C137: 1263.5 | D137: 1244.45 | E137: 1248.9 | F137: 1260.1 | G137: 1254.48 | H137: 1,03,68,438 | I137: 13,00,69,59,974.75 | J137: 2,89,728 | K137: =(F137-F136)/F136 -> 0.0089678917 | L137: -0.0044352493 | M137: =VALUE(SUBSTITUTE(H137,",","")) -> 10368438
...

Sheet ITC
A1: DATE | B1: OPEN | C1: HIGH | D1: LOW | E1: PREV. CLOSE | F1: CLOSE | G1: VWAP | H1: VOLUME | I1: VALUE | J1: NO. OF TRADES | K1: DAILY RETURN | L1: NIFTY RETURN
A2: 45509 | B2: 480.05 | C2: 491.9 | D2: 479.55 | E2: 489.1 | F2: 486 | G2: 485.81 | H2: 2,40,94,139 | I2: 11,70,52,82,411.05 | J2: 2,40,878 | M2: =VALUE(SUBSTITUTE(H2,",","")) -> 24094139
A3: 45510 | B3: 486.25 | C3: 491.7 | D3: 484.05 | E3: 486 | F3: 486.3 | G3: 487.52 | H3: 1,37,22,855 | I3: 6,69,01,15,892.10 | J3: 1,65,576 | K3: =(F3-F2)/F2 -> 0.00061728395 | L3: -0.0026210113 | M3: =VALUE(SUBSTITUTE(H3,",","")) -> 13722855
A4: 45511 | B4: 490 | C4: 495.6 | D4: 488.1 | E4: 486.3 | F4: 492.65 | G4: 491.96 | H4: 1,09,00,585 | I4: 5,36,26,50,358.25 | J4: 1,73,490 | K4: =(F4-F3)/F3 -> 0.013057783 | L4: 0.012710195 | M4: =VALUE(SUBSTITUTE(H4,",","")) -> 10900585
A5: 45512 | B5: 494 | C5: 498 | D5: 492.5 | E5: 492.65 | F5: 494.75 | G5: 494.99 | H5: 2,05,58,134 | I5: 10,17,59,99,936.05 | J5: 2,50,724 | K5: =(F5-F4)/F4 -> 0.0042626611 | L5: -0.0074287478 | M5: =VALUE(SUBSTITUTE(H5,",","")) -> 20558134
A6: 45513 | B6: 498 | C6: 498 | D6: 493.1 | E6: 494.75 | F6: 495.9 | G6: 495.38 | H6: 92,01,793 | I6: 4,55,83,87,017.25 | J6: 1,44,367 | K6: =(F6-F5)/F5 -> 0.0023244063 | L6: 0.010386864 | M6: =VALUE(SUBSTITUTE(H6,",","")) -> 9201793
A7: 45516 | B7: 492 | C7: 500 | D7: 492 | E7: 495.9 | F7: 494.6 | G7: 497.04 | H7: 90,76,097 | I7: 4,51,11,89,537.95 | J7: 1,33,143 | K7: =(F7-F6)/F6 -> -0.0026214963 | L7: -0.0008412845 | M7: =VALUE(SUBSTITUTE(H7,",","")) -> 9076097
A8: 45517 | B8: 495.95 | C8: 497.85 | D8: 488.25 | E8: 494.6 | F8: 490 | G8: 493.29 | H8: 77,57,706 | I8: 3,82,67,62,550.05 | J8: 1,19,952 | K8: =(F8-F7)/F7 -> -0.0093004448 | L8: -0.008543147 | M8: =VALUE(SUBSTITUTE(H8,",","")) -> 7757706
A9: 45518 | B9: 491.95 | C9: 499 | D9: 489.9 | E9: 490 | F9: 492.2 | G9: 494.04 | H9: 92,53,598 | I9: 4,57,16,25,348.00 | J9: 1,50,643 | K9: =(F9-F8)/F8 -> 0.0044897959 | L9: 0.000196777 | M9: =VALUE(SUBSTITUTE(H9,",","")) -> 9253598
A10: 45520 | B10: 494.5 | C10: 504.2 | D10: 492.65 | E10: 492.2 | F10: 502.65 | G10: 498.53 | H10: 1,31,37,392 | I10: 6,54,94,43,406.85 | J10: 1,64,043 | K10: =(F10-F9)/F9 -> 0.021231207 | L10: 0.016459746 | M10: =VALUE(SUBSTITUTE(H10,",","")) -> 13137392
A11: 45523 | B11: 504.75 | C11: 509.3 | D11: 499.6 | E11: 502.65 | F11: 501.45 | G11: 504.39 | H11: 1,01,98,725 | I11: 5,14,41,20,039.10 | J11: 1,66,648 | K11: =(F11-F10)/F10 -> -0.0023873471 | L11: 0.0012835584 | M11: =VALUE(SUBSTITUTE(H11,",","")) -> 10198725
A12: 45524 | B12: 501 | C12: 503.4 | D12: 497.7 | E12: 501.45 | F12: 498.8 | G12: 499.95 | H12: 66,33,171 | I12: 3,31,62,78,832.00 | J12: 1,15,083 | K12: =(F12-F11)/F11 -> -0.0052846744 | L12: 0.0051357912 | M12: =VALUE(SUBSTITUTE(H12,",","")) -> 6633171
A13: 45525 | B13: 500 | C13: 509 | D13: 499.05 | E13: 498.8 | F13: 505.4 | G13: 505.03 | H13: 84,74,830 | I13: 4,28,00,48,280.45 | J13: 1,21,930 | K13: =(F13-F12)/F12 -> 0.013231756 | L13: 0.0028887985 | M13: =VALUE(SUBSTITUTE(H13,",","")) -> 8474830
A14: 45526 | B14: 507.85 | C14: 508.5 | D14: 501.45 | E14: 505.4 | F14: 504.55 | G14: 504.67 | H14: 83,64,290 | I14: 4,22,12,24,253.25 | J14: 1,45,029 | K14: =(F14-F13)/F13 -> -0.0016818362 | L14: 0.0016673261 | M14: =VALUE(SUBSTITUTE(H14,",","")) -> 8364290
... A30: 45548 | B30: 519.5 | C30: 520 | D30: 512 | E30: 519.5 | F30: 513.85 | G30: 513.81 | H30: 88,25,193 | I30: 4,53,44,84,027.05 | J30: 1,39,096 | K30: =(F30-F29)/F29 -> -0.010875842 | L30: -0.0012761482 | M30: =VALUE(SUBSTITUTE(H30,",","")) -> 8825193
A31: 45551 | B31: 515.9 | C31: 517 | D31: 509.7 | E31: 513.85 | F31: 511.1 | G31: 513.15 | H31: 75,31,604 | I31: 3,86,48,31,357.30 | J31: 80552 | K31: =(F31-F30)/F30 -> -0.0053517563 | L31: 0.0010746751 | M31: =VALUE(SUBSTITUTE(H31,",","")) -> 7531604
A32: 45552 | B32: 511.05 | C32: 513.55 | D32: 506.25 | E32: 511.1 | F32: 507.75 | G32: 508.55 | H32: 1,04,86,015 | I32: 5,33,26,81,431.45 | J32: 1,13,046 | K32: =(F32-F31)/F31 -> -0.0065544903 | L32: 0.0013709558 | M32: =VALUE(SUBSTITUTE(H32,",","")) -> 10486015
A33: 45553 | B33: 507.85 | C33: 512.4 | D33: 505.1 | E33: 507.75 | F33: 507.35 | G33: 509.15 | H33: 54,29,619 | I33: 2,76,45,06,352.10 | J33: 98908 | K33: =(F33-F32)/F32 -> -0.00078778927 | L33: -0.0016129952 | M33: =VALUE(SUBSTITUTE(H33,",","")) -> 5429619
A34: 45554 | B34: 510 | C34: 514.8 | D34: 507.5 | E34: 507.35 | F34: 508.25 | G34: 510.59 | H34: 1,39,25,311 | I34: 7,11,00,66,899.10 | J34: 2,26,927 | K34: =(F34-F33)/F33 -> 0.0017739233 | L34: 0.0015072377 | M34: =VALUE(SUBSTITUTE(H34,",","")) -> 13925311
A35: 45555 | B35: 512 | C35: 517.35 | D35: 508 | E35: 508.25 | F35: 514.4 | G35: 513.97 | H35: 2,38,08,194 | I35: 12,23,67,58,568.15 | J35: 2,31,527 | K35: =(F35-F34)/F34 -> 0.012100344 | L35: 0.014760503 | M35: =VALUE(SUBSTITUTE(H35,",","")) -> 23808194
A36: 45558 | B36: 515.45 | C36: 519.45 | D36: 513.6 | E36: 514.4 | F36: 516.95 | G36: 516.88 | H36: 78,04,918 | I36: 4,03,42,41,784.00 | J36: 1,30,984 | K36: =(F36-F35)/F35 -> 0.0049572317 | L36: 0.0057423243 | M36: =VALUE(SUBSTITUTE(H36,",","")) -> 7804918
A37: 45559 | B37: 517 | C37: 517.8 | D37: 514.15 | E37: 516.95 | F37: 515.25 | G37: 515.47 | H37: 67,55,320 | I37: 3,48,21,95,547.40 | J37: 1,21,014 | K37: =(F37-F36)/F36 -> -0.0032885192 | L37: 5.2045083e-05 | M37: =VALUE(SUBSTITUTE(H37,",","")) -> 6755320
A38: 45560 | B38: 515.5 | C38: 519.3 | D38: 512.3 | E38: 515.25 | F38: 517.55 | G38: 515.67 | H38: 84,76,223 | I38: 4,37,09,74,903.20 | J38: 1,55,236 | K38: =(F38-F37)/F37 -> 0.0044638525 | L38: 0.0024575566 | M38: =VALUE(SUBSTITUTE(H38,",","")) -> 8476223
A39: 45561 | B39: 517.65 | C39: 523.75 | D39: 517 | E39: 517.55 | F39: 522.75 | G39: 521.19 | H39: 1,54,89,991 | I39: 8,07,31,86,016.75 | J39: 2,03,237 | K39: =(F39-F38)/F38 -> 0.010047338 | L39: 0.0081486993 | M39: =VALUE(SUBSTITUTE(H39,",","")) -> 15489991
A40: 45562 | B40: 520.25 | C40: 528.5 | D40: 520.25 | E40: 522.75 | F40: 522.7 | G40: 524.14 | H40: 1,72,51,962 | I40: 9,04,23,61,720.15 | J40: 1,69,240 | K40: =(F40-F39)/F39 -> -9.5648015e-05 | L40: -0.0014151636 | M40: =VALUE(SUBSTITUTE(H40,",","")) -> 17251962
A41: 45565 | B41: 520.6 | C41: 524.35 | D41: 514.05 | E41: 522.7 | F41: 518.15 | G41: 518.56 | H41: 1,05,31,347 | I41: 5,46,11,48,445.10 | J41: 1,63,844 | K41: =(F41-F40)/F40 -> -0.008704802 | L41: -0.014060915 | M41: =VALUE(SUBSTITUTE(H41,",","")) -> 10531347
A42: 45566 | B42: 518.15 | C42: 519.75 | D42: 514 | E42: 518.15 | F42: 516.2 | G42: 515.9 | H42: 50,89,315 | I42: 2,62,55,80,578.35 | J42: 1,09,488 | K42: =(F42-F41)/F41 -> -0.003763389 | L42: -0.00054047038 | M42: =VALUE(SUBSTITUTE(H42,",","")) -> 5089315
A43: 45568 | B43: 508.55 | C43: 515.7 | D43: 508.1 | E43: 516.2 | F43: 512.75 | G43: 512.47 | H43: 1,58,70,147 | I43: 8,13,29,38,477.90 | J43: 2,27,553 | K43: =(F43-F42)/F42 -> -0.006683456 | L43: -0.021196345 | M43: =VALUE(SUBSTITUTE(H43,",","")) -> 15870147
A44: 45569 | B44: 510 | C44: 517.35 | D44: 501.55 | E44: 512.75 | F44: 503.55 | G44: 509.93 | H44: 1,82,28,912 | I44: 9,29,54,09,035.50 | J44: 2,92,636 | K44: =(F44-F43)/F43 -> -0.017942467 | L44: -0.0093266957 | M44: =VALUE(SUBSTITUTE(H44,",","")) -> 18228912
A45: 45572 | B45: 507 | C45: 514.95 | D45: 506.75 | E45: 503.55 | F45: 510.2 | G45: 511.03 | H45: 1,64,79,772 | I45: 8,42,16,88,874.45 | J45: 2,16,682 | K45: =(F45-F44)/F44 -> 0.013206236 | L45: -0.0087488906 | M45: =VALUE(SUBSTITUTE(H45,",","")) -> 16479772
... A61: 45594 | B61: 485 | C61: 489.2 | D61: 481.3 | E61: 484.15 | F61: 487.95 | G61: 486.12 | H61: 68,66,704 | I61: 3,33,80,33,179.65 | J61: 1,11,564 | K61: =(F61-F60)/F60 -> 0.0078488072 | L61: 0.005246691 | M61: =VALUE(SUBSTITUTE(H61,",","")) -> 6866704
A62: 45595 | B62: 487.95 | C62: 493.25 | D62: 486.5 | E62: 487.95 | F62: 491.55 | G62: 490.85 | H62: 63,93,835 | I62: 3,13,83,98,995.85 | J62: 92835 | K62: =(F62-F61)/F61 -> 0.0073778051 | L62: -0.0051498252 | M62: =VALUE(SUBSTITUTE(H62,",","")) -> 6393835
A63: 45596 | B63: 492 | C63: 493 | D63: 484.7 | E63: 491.55 | F63: 488.8 | G63: 487.8 | H63: 78,10,874 | I63: 3,81,01,27,063.40 | J63: 1,61,609 | K63: =(F63-F62)/F62 -> -0.0055945479 | L63: -0.0055667736 | M63: =VALUE(SUBSTITUTE(H63,",","")) -> 7810874
A64: 45597 | B64: 491 | C64: 492.1 | D64: 489.3 | E64: 488.8 | F64: 490.3 | G64: 490.89 | H64: 14,61,602 | I64: 71,74,91,831.90 | J64: 54687 | K64: =(F64-F63)/F63 -> 0.0030687398 | L64: 0.0040900049 | M64: =VALUE(SUBSTITUTE(H64,",","")) -> 1461602
A65: 45600 | B65: 493.45 | C65: 493.45 | D65: 479.55 | E65: 490.3 | F65: 484.6 | G65: 483.55 | H65: 84,29,731 | I65: 4,07,61,59,422.90 | J65: 1,70,904 | K65: =(F65-F64)/F64 -> -0.011625535 | L65: -0.012713773 | M65: =VALUE(SUBSTITUTE(H65,",","")) -> 8429731
